Workbook

Sheet Panel
B2: Cronograma de entregables y desembolsos
B3: Convenio de Donación N.° 130P-2025000001 · CARE (Asociación Central Asháninka del Río Ene) y Profonanpe · Proyecto ASL2 · Plazos vigentes de la Adenda N.° 01 (27/04/2026)
B4: ▸ Entregables | D4: ▸ Desembolsos | F4: ▸ Vistas por estado | H4: ▸ Línea de tiempo | J4: ▸ Comparativo | L4: ▸ Paso a paso | N4: ▸ Dudas
B6: Fecha ref. (vacío = hoy) | D6: Fecha usada | F6: Aviso «por vencer» (días) | H6: Filtro de la tabla de productos | K6: Producto a consultar (ficha)
D7: =IF(B7="",TODAY(),B7) -> 46309 | F7: 30 | H7: Todos | K7: Producto 3
B8: Celdas amarillas = editables. Los botones de color abren la lista de cada estado. Registra entregas, revisiones, pagos y rendiciones en las hojas Entregables y Desembolsos.
B10: PRÓXIMO VENCIMIENTO | F10: PRODUCTOS VENCIDOS | I10: PRODUCTOS POR VENCER | L10: PRODUCTOS ENTREGADOS / APROBADOS
B11: =IF('Datos gráficos'!$C$42=0,"Sin pendientes",'Datos gráficos'!$C$42) -> 46374 | F11: ='Datos gráficos'!$C$45 -> 2 | I11: ='Datos gráficos'!$C$46 -> 0 | L11: ='Datos gráficos'!$C$47&" de 5 · "&'Datos gráficos'!$C$48&" aprob." -> 1 de 5 · 0 aprob.
B12: =IF('Datos gráficos'!$C$42=0,"No quedan productos con fecha futura.",'Datos gráficos'!$C$43&": vence en "&'Datos gráficos'!$C$44&" días") -> Producto 3: vence en 65 días | F12: =IF('Datos gráficos'!$C$45>0,"Sin marcar como entregados.","Ninguno para la fecha de referencia.") -> Sin marcar como entregados. | I12: ="En los próximos "&DiasAviso&" días." -> En los próximos 30 días. | L12: ="Avance físico (Adenda): "&TEXT('Datos gráficos'!$C$49*100,"0")&" % · Observados: "&'Datos gráficos'!$C$59 -> Avance físico (Adenda): 30 % · Observados: 0
B14: MONTO DEL CONVENIO A CARE | F14: DESEMBOLSADO | I14: LISTO PARA SOLICITAR | L14: SALDO POR RENDIR
B15: =TotalCARE -> 471250 | F15: ='Datos gráficos'!$C$14 -> 0 | I15: ='Datos gráficos'!$C$15 -> 0 | L15: ='Datos gráficos'!$C$57 -> 0
B16: ="Tope Profonanpe S/ "&FIXED(Parámetros!C10,2)&" con compra directa" -> Tope Profonanpe S/ 511,250.00 con compra directa | F16: =TEXT('Datos gráficos'!$C$50*100,"0")&" % del monto" -> 0 % del monto | I16: ="En conformidad: S/ "&FIXED('Datos gráficos'!$C$17,0)&" · Falta rendir: S/ "&FIXED('Datos gráficos'!$C$16,0) -> En conformidad: S/ 141,375 · Falta rendir: S/ 0 | L16: ="Rendido: S/ "&FIXED('Datos gráficos'!$C$58,2)&" · Dudas abiertas: "&'Datos gráficos'!$C$54 -> Rendido: S/ 0.00 · Dudas abiertas: 7
B18: =IF('Datos gráficos'!$C$45>0,"⚠ "&'Datos gráficos'!$C$45&IF('Datos gráficos'!$C$45=1," producto figura como vencido"," productos figuran como vencidos")&". Si ya se entregaron, marca «Sí» en la hoja Entregables (columna L).",IF('Datos gráficos'!$C$46>0,"⏳ "&'Datos gráficos'!$C$46&" producto(s) por vencer en los próximos "&DiasAviso&" días.","✓ Sin productos vencidos ni por vencer para la fecha de referencia.")) -> ⚠ 2 productos figuran como vencidos. Si ya se entregaron, marca «Sí» en la hoja Entregables (columna L).
B20: Botones de estado · Productos (haz clic para ver la lista)
B21: ="TODOS"&CHAR(10)&5 -> TODOS 5 | D21: ="POR ENTREGAR"&CHAR(10)&'Datos gráficos'!$C$27 -> POR ENTREGAR 2 | F21: ="POR VENCER"&CHAR(10)&'Datos gráficos'!$C$28 -> POR VENCER 0 | H21: ="VENCIDOS"&CHAR(10)&'Datos gráficos'!$C$29 -> VENCIDOS 2 | J21: ="EN REVISIÓN"&CHAR(10)&'Datos gráficos'!$C$30 -> EN REVISIÓN 1 | L21: ="OBSERVADO"&CHAR(10)&'Datos gráficos'!$C$31 -> OBSERVADO 0 | N21: ="APROBADO"&CHAR(10)&'Datos gráficos'!$C$32 -> APROBADO 0
B24: Botones de estado · Desembolsos (haz clic para ver la lista)
B25: ="TODOS"&CHAR(10)&4 -> TODOS 4 | D25: ="DESEMBOLSADO"&CHAR(10)&'Datos gráficos'!$C$35 -> DESEMBOLSADO 0 | F25: ="LISTO PARA SOLICITAR"&CHAR(10)&'Datos gráficos'!$C$36 -> LISTO PARA SOLICITAR 0 | H25: ="FALTA RENDICIÓN"&CHAR(10)&'Datos gráficos'!$C$37 -> FALTA RENDICIÓN 0 | J25: ="EN CONFORMIDAD"&CHAR(10)&'Datos gráficos'!$C$38 -> EN CONFORMIDAD 1 | L25: ="PENDIENTE DE PRODUCTO"&CHAR(10)&'Datos gráficos'!$C$39 -> PENDIENTE DE PRODUCTO 3 | N25: ="RENDICIONES"&CHAR(10)&"S/ "&FIXED('Datos gráficos'!$C$57,0)&" por rendir" -> RENDICIONES S/ 0 por rendir
B28: Avance físico (productos entregados, % Adenda) | G28: ='Datos gráficos'!$C$49 -> 0.3 | H28: ='Datos gráficos'!$C$49 -> 0.3
B29: Ejecución financiera (desembolsado / total) | G29: ='Datos gráficos'!$C$50 -> 0 | H29: ='Datos gráficos'!$C$50 -> 0
B30: Rendición (rendido / desembolsado) | G30: ='Datos gráficos'!$C$51 -> 0 | H30: ='Datos gráficos'!$C$51 -> 0
B31: Tiempo transcurrido del convenio | G31: ='Datos gráficos'!$C$52 -> 0.61629881 | H31: ='Datos gráficos'!$C$52 -> 0.61629881 | M31: ="Faltan "&'Datos gráficos'!$C$53&" días al cierre ("&RIGHT("0"&DAY(Cierre),2)&"/"&RIGHT("0"&MONTH(Cierre),2)&"/"&YEAR(Cierre)&")" -> Faltan 226 días al cierre (28/05/2027)
B33: Línea de tiempo de los productos (plazos de la Adenda N.° 01)
B52: ="Fecha de referencia: "&RIGHT("0"&DAY(FechaRef),2)&"/"&RIGHT("0"&MONTH(FechaRef),2)&"/"&YEAR(FechaRef)&". Detalle semanal con la semana actual marcada en la hoja «Línea de tiempo»." -> Fecha de referencia: 14/10/2026. Detalle semanal con la semana actual marcada en la hoja «Línea de tiempo».
B54: ="Productos · filtro: "&FiltroEstado&" ("&'Datos gráficos'!$C$55&" de 5) — cambia el filtro en la celda H7" -> Productos · filtro: Todos (5 de 5) — cambia el filtro en la celda H7
B55: Producto | D55: Título | G55: Fecha límite | H55: Días restantes | I55: Estado | K55: Situación | O55: Desemb.
B56: =IFERROR(INDEX(Entregables!$D$5:$D$9,MATCH(1,Entregables!$AB$5:$AB$9,0)),"") -> Producto 1 | D56: =IFERROR(INDEX(Entregables!$E$5:$E$9,MATCH(1,Entregables!$AB$5:$AB$9,0)),"") -> Plan de trabajo y cronograma | G56: =IFERROR(INDEX(Entregables!$H$5:$H$9,MATCH(1,Entregables!$AB$5:$AB$9,0)),"") -> 46011 | H56: =IFERROR(INDEX(Entregables!$R$5:$R$9,MATCH(1,Entregables!$AB$5:$AB$9,0)),"") -> -298 | I56: =IFERROR(INDEX(Entregables!$S$5:$S$9,MATCH(1,Entregables!$AB$5:$AB$9,0)),"") -> En revisión | K56: =IFERROR(INDEX(Entregables!$T$5:$T$9,MATCH(1,Entregables!$AB$5:$AB$9,0)),"") -> Presentado el 30/11/2025; espera conformidad UGP/FAO | O56: =IFERROR(INDEX(Entregables!$K$5:$K$9,MATCH(1,Entregables!$AB$5:$AB$9,0)),"") -> D1
B57: =IFERROR(INDEX(Entregables!$D$5:$D$9,MATCH(2,Entregables!$AB$5:$AB$9,0)),"") -> Producto 2 · Parte I | D57: =IFERROR(INDEX(Entregables!$E$5:$E$9,MATCH(2,Entregables!$AB$5:$AB$9,0)),"") -> Plan de capacitación y avances | G57: =IFERROR(INDEX(Entregables!$H$5:$H$9,MATCH(2,Entregables!$AB$5:$AB$9,0)),"") -> 46142 | H57: =IFERROR(INDEX(Entregables!$R$5:$R$9,MATCH(2,Entregables!$AB$5:$AB$9,0)),"") -> -167 | I57: =IFERROR(INDEX(Entregables!$S$5:$S$9,MATCH(2,Entregables!$AB$5:$AB$9,0)),"") -> Vencido | K57: =IFERROR(INDEX(Entregables!$T$5:$T$9,MATCH(2,Entregables!$AB$5:$AB$9,0)),"") -> Venció hace 167 días | O57: =IFERROR(INDEX(Entregables!$K$5:$K$9,MATCH(2,Entregables!$AB$5:$AB$9,0)),"") -> D2
B58: =IFERROR(INDEX(Entregables!$D$5:$D$9,MATCH(3,Entregables!$AB$5:$AB$9,0)),"") -> Producto 2 · Parte II | D58: =IFERROR(INDEX(Entregables!$E$5:$E$9,MATCH(3,Entregables!$AB$5:$AB$9,0)),"") -> Plan de recuperación y fichas | G58: =IFERROR(INDEX(Entregables!$H$5:$H$9,MATCH(3,Entregables!$AB$5:$AB$9,0)),"") -> 46203 | H58: =IFERROR(INDEX(Entregables!$R$5:$R$9,MATCH(3,Entregables!$AB$5:$AB$9,0)),"") -> -106 | I58: =IFERROR(INDEX(Entregables!$S$5:$S$9,MATCH(3,Entregables!$AB$5:$AB$9,0)),"") -> Vencido | K58: =IFERROR(INDEX(Entregables!$T$5:$T$9,MATCH(3,Entregables!$AB$5:$AB$9,0)),"") -> Venció hace 106 días | O58: =IFERROR(INDEX(Entregables!$K$5:$K$9,MATCH(3,Entregables!$AB$5:$AB$9,0)),"") -> D2
B59: =IFERROR(INDEX(Entregables!$D$5:$D$9,MATCH(4,Entregables!$AB$5:$AB$9,0)),"") -> Producto 3 | D59: =IFERROR(INDEX(Entregables!$E$5:$E$9,MATCH(4,Entregables!$AB$5:$AB$9,0)),"") -> Pasantía, plantaciones y planes de vida | G59: =IFERROR(INDEX(Entregables!$H$5:$H$9,MATCH(4,Entregables!$AB$5:$AB$9,0)),"") -> 46374 | H59: =IFERROR(INDEX(Entregables!$R$5:$R$9,MATCH(4,Entregables!$AB$5:$AB$9,0)),"") -> 65 | I59: =IFERROR(INDEX(Entregables!$S$5:$S$9,MATCH(4,Entregables!$AB$5:$AB$9,0)),"") -> Por entregar | K59: =IFERROR(INDEX(Entregables!$T$5:$T$9,MATCH(4,Entregables!$AB$5:$AB$9,0)),"") -> Vence en 65 días | O59: =IFERROR(INDEX(Entregables!$K$5:$K$9,MATCH(4,Entregables!$AB$5:$AB$9,0)),"") -> D3
B60: =IFERROR(INDEX(Entregables!$D$5:$D$9,MATCH(5,Entregables!$AB$5:$AB$9,0)),"") -> Producto 4 | D60: =IFERROR(INDEX(Entregables!$E$5:$E$9,MATCH(5,Entregables!$AB$5:$AB$9,0)),"") -> Informe final y resultados | G60: =IFERROR(INDEX(Entregables!$H$5:$H$9,MATCH(5,Entregables!$AB$5:$AB$9,0)),"") -> 46507 | H60: =IFERROR(INDEX(Entregables!$R$5:$R$9,MATCH(5,Entregables!$AB$5:$AB$9,0)),"") -> 198 | I60: =IFERROR(INDEX(Entregables!$S$5:$S$9,MATCH(5,Entregables!$AB$5:$AB$9,0)),"") -> Por entregar | K60: =IFERROR(INDEX(Entregables!$T$5:$T$9,MATCH(5,Entregables!$AB$5:$AB$9,0)),"") -> Vence en 198 días | O60: =IFERROR(INDEX(Entregables!$K$5:$K$9,MATCH(5,Entregables!$AB$5:$AB$9,0)),"") -> D4
B61: =IF('Datos gráficos'!$C$55=0,"No hay productos en este estado para la fecha de referencia.","")
B63: Desembolsos (cláusula novena) y rendiciones
B64: Desemb. | C64: Monto | E64: Lo habilita | G64: Fecha límite producto | H64: ¿Aprobado? | I64: ¿Rendición previa? | J64: Estado | L64: Siguiente paso | O64: Fecha de pago
B65: =Desembolsos!A5 -> D1 | C65: =Desembolsos!B5 -> 141375 | E65: =Desembolsos!G5 -> Producto 1 | G65: =Desembolsos!I5 -> 46011 | H65: =Desembolsos!L5 -> No | I65: =Desembolsos!N5 -> Sí | J65: =Desembolsos!T5 -> En conformidad | L65: =Desembolsos!U5 -> Conseguir la opinión técnica del Componente 2 y las conformidades del Coordinador y de FAO | O65: =IF(Desembolsos!P5="","",Desembolsos!P5)
B66: =Desembolsos!A6 -> D2 | C66: =Desembolsos!B6 -> 141375 | E66: =Desembolsos!G6 -> Producto 2 (Parte I y Parte II) | G66: =Desembolsos!I6 -> 46203 | H66: =Desembolsos!L6 -> No | I66: =Desembolsos!N6 -> No | J66: =Desembolsos!T6 -> Pendiente de producto | L66: =Desembolsos!U6 -> Presentar Producto 2 (Parte I y Parte II) (vence el 30/06/2026) | O66: =IF(Desembolsos!P6="","",Desembolsos!P6)
B67: =Desembolsos!A7 -> D3 | C67: =Desembolsos!B7 -> 117812 | E67: =Desembolsos!G7 -> Producto 3 | G67: =Desembolsos!I7 -> 46374 | H67: =Desembolsos!L7 -> No | I67: =Desembolsos!N7 -> No | J67: =Desembolsos!T7 -> Pendiente de producto | L67: =Desembolsos!U7 -> Presentar Producto 3 (vence el 18/12/2026) | O67: =IF(Desembolsos!P7="","",Desembolsos!P7)
B68: =Desembolsos!A8 -> D4 | C68: =Desembolsos!B8 -> 70688 | E68: =Desembolsos!G8 -> Producto 4 | G68: =Desembolsos!I8 -> 46507 | H68: =Desembolsos!L8 -> No | I68: =Desembolsos!N8 -> No | J68: =Desembolsos!T8 -> Pendiente de producto | L68: =Desembolsos!U8 -> Presentar Producto 4 (vence el 30/04/2027) | O68: =IF(Desembolsos!P8="","",Desembolsos!P8)
B69: Total | C69: =TotalCARE -> 471250 | E69: Montos y requisitos de la cláusula 9.1. La rendición previa exige el 70 % del pago anterior (y el 100 % del penúltimo).
B71: Indicadores gráficos
B72: Estado del dinero (S/ 471,250) | G72: Monto por desembolso y estado | L72: Productos por estado
...

Sheet Entregables
B1: ← Volver al Panel
B2: Entregables (plazos vigentes de la Adenda N.° 01)
B3: Cláusula sexta modificada por la Adenda N.° 01 (27/04/2026). Días calendario contados desde la fecha de inicio (Parámetros). | L3: ▼ Edita las columnas amarillas (L a Q)
A4: Código | B4: Producto | C4: Parte | D4: Etiqueta | E4: Título | F4: Plazo Adenda (días) | G4: Inicio de ventana | H4: Fecha límite (Adenda) | I4: Día de inicio | J4: % avance (Adenda) | K4: Desembolso | L4: ¿Entregado? | M4: Fecha de entrega real | N4: Revisión UGP / FAO | O4: Fecha de observación | P4: Plazo para subsanar | Q4: Fecha de conformidad | R4: Días restantes | S4: Estado | T4: Situación | U4: Puntualidad | V4: Plazo original (días) | W4: Fecha original | X4: Días de prórroga | Y4: Conformidad FAO en | Z4: Contenidos | AA4: Coincide filtro | AB4: Orden filtro | AC4: Todos | AD4: Por entregar | AE4: Por vencer | AF4: Vencido | AG4: En revisión | AH4: Observado | AI4: Aprobado
A5: P1 | B5: Producto 1 | D5: =B5&IF(C5="",""," · "&C5) -> Producto 1 | E5: Plan de trabajo y cronograma | F5: 65 | G5: =Inicio -> 45946 | H5: =Inicio+F5 -> 46011 | I5: 0 | J5: 0.3 | K5: D1 | L5: Sí | M5: 45991 | N5: En revisión | P5: =IF(O5="","",O5+DiasSubsanar) | R5: =H5-FechaRef -> -298 | S5: =IF(L5="Sí",IF(N5="Conforme","Aprobado",IF(N5="Observado","Observado","En revisión")),IF(R5<0,"Vencido",IF(R5<=DiasAviso,"Por vencer","Por entregar"))) -> En revisión | T5: =IF(S5="Aprobado","Conforme"&IF(Q5<>""," desde el "&RIGHT("0"&DAY(Q5),2)&"/"&RIGHT("0"&MONTH(Q5),2)&"/"&YEAR(Q5),""),IF(S5="Observado",IF(P5="","Observado: registra la fecha de observación",IF(P5>=FechaRef,"Subsanar hasta el "&RIGHT("0"&DAY(P5),2)&"/"&RIGHT("0"&MONTH(P5),2)&"/"&YEAR(P5)&" (faltan "&(P5-FechaRef)&" días)","Plazo para subsanar vencido el "&RIGHT("0"&DAY(P5),2)&"/"&RIGHT("0"&MONTH(P5),2)&"/"&YEAR(P5))),IF(S5="En revisión",IF(M5<>"","Presentado el "&RIGHT("0"&DAY(M5),2)&"/"&RIGHT("0"&MONTH(M5),2)&"/"&YEAR(M5)&"; espera conformidad UGP/FAO","Entregado; espera conformidad UGP/FAO"),IF(R5<0,"Venció hace "&-R5&IF(R5=-1," día"," días"),IF(R5=0,"Vence hoy","Vence en "&R5&IF(R5=1," día"," días")))))) -> Presentado el 30/11/2025; espera conformidad UGP/FAO | U5: =IF(L5<>"Sí","",IF(M5="","Sin fecha registrada",IF(M5<=H5,"A tiempo","Con "&(M5-H5)&" días de retraso"))) -> A tiempo | V5: 15 | W5: =Inicio+V5 -> 45961 | X5: =F5-V5 -> 50 | Y5: el plan de trabajo y la metodología | Z5: • Plan de trabajo detallado (actividades, subactividades, indicadores de avance), metodología y cronograma a 18 meses. (*) | AA5: =OR(FiltroEstado="Todos",S5=FiltroEstado) -> TRUE | AB5: =IF(AA5,COUNTIF($AA$5:AA5,TRUE()),"") -> 1 | AC5: =ROW()-4 -> 1 | AD5: =IF($S5=AD$4,COUNTIF($S$5:$S5,AD$4),"") | AE5: =IF($S5=AE$4,COUNTIF($S$5:$S5,AE$4),"") | AF5: =IF($S5=AF$4,COUNTIF($S$5:$S5,AF$4),"") | AG5: =IF($S5=AG$4,COUNTIF($S$5:$S5,AG$4),"") -> 1 | AH5: =IF($S5=AH$4,COUNTIF($S$5:$S5,AH$4),"") | AI5: =IF($S5=AI$4,COUNTIF($S$5:$S5,AI$4),"")
A6: P2-I | B6: Producto 2 | C6: Parte I | D6: =B6&IF(C6="",""," · "&C6) -> Producto 2 · Parte I | E6: Plan de capacitación y avances | F6: 196 | G6: =H5+1 -> 46012 | H6: =Inicio+F6 -> 46142 | I6: =F5+1 -> 66 | J6: 0.2 | K6: D2 | L6: No | P6: =IF(O6="","",O6+DiasSubsanar) | R6: =H6-FechaRef -> -167 | S6: =IF(L6="Sí",IF(N6="Conforme","Aprobado",IF(N6="Observado","Observado","En revisión")),IF(R6<0,"Vencido",IF(R6<=DiasAviso,"Por vencer","Por entregar"))) -> Vencido | T6: =IF(S6="Aprobado","Conforme"&IF(Q6<>""," desde el "&RIGHT("0"&DAY(Q6),2)&"/"&RIGHT("0"&MONTH(Q6),2)&"/"&YEAR(Q6),""),IF(S6="Observado",IF(P6="","Observado: registra la fecha de observación",IF(P6>=FechaRef,"Subsanar hasta el "&RIGHT("0"&DAY(P6),2)&"/"&RIGHT("0"&MONTH(P6),2)&"/"&YEAR(P6)&" (faltan "&(P6-FechaRef)&" días)","Plazo para subsanar vencido el "&RIGHT("0"&DAY(P6),2)&"/"&RIGHT("0"&MONTH(P6),2)&"/"&YEAR(P6))),IF(S6="En revisión",IF(M6<>"","Presentado el "&RIGHT("0"&DAY(M6),2)&"/"&RIGHT("0"&MONTH(M6),2)&"/"&YEAR(M6)&"; espera conformidad UGP/FAO","Entregado; espera conformidad UGP/FAO"),IF(R6<0,"Venció hace "&-R6&IF(R6=-1," día"," días"),IF(R6=0,"Vence hoy","Vence en "&R6&IF(R6=1," día"," días")))))) -> Venció hace 167 días | U6: =IF(L6<>"Sí","",IF(M6="","Sin fecha registrada",IF(M6<=H6,"A tiempo","Con "&(M6-H6)&" días de retraso"))) | V6: 180 | W6: =Inicio+V6 -> 46126 | X6: =F6-V6 -> 16 | Y6: el plan de fortalecimiento de capacidades | Z6: • Plan de capacitación en recuperación: perfiles, competencias, capacidades e indicadores de logro. (*) • Informe de ejecución de los módulos 1 y 2 del plan de capacitación en recuperación y conectividad «Tsimeeri». • Informe de avances en planes de vida en las 03 CCNN. | AA6: =OR(FiltroEstado="Todos",S6=FiltroEstado) -> TRUE | AB6: =IF(AA6,COUNTIF($AA$5:AA6,TRUE()),"") -> 2 | AC6: =ROW()-4 -> 2 | AD6: =IF($S6=AD$4,COUNTIF($S$5:$S6,AD$4),"") | AE6: =IF($S6=AE$4,COUNTIF($S$5:$S6,AE$4),"") | AF6: =IF($S6=AF$4,COUNTIF($S$5:$S6,AF$4),"") -> 1 | AG6: =IF($S6=AG$4,COUNTIF($S$5:$S6,AG$4),"") | AH6: =IF($S6=AH$4,COUNTIF($S$5:$S6,AH$4),"") | AI6: =IF($S6=AI$4,COUNTIF($S$5:$S6,AI$4),"")
A7: P2-II | B7: Producto 2 | C7: Parte II | D7: =B7&IF(C7="",""," · "&C7) -> Producto 2 · Parte II | E7: Plan de recuperación y fichas | F7: 257 | G7: =H6+1 -> 46143 | H7: =Inicio+F7 -> 46203 | I7: =F6+1 -> 197 | J7: 0.15 | K7: D2 | L7: No | P7: =IF(O7="","",O7+DiasSubsanar) | R7: =H7-FechaRef -> -106 | S7: =IF(L7="Sí",IF(N7="Conforme","Aprobado",IF(N7="Observado","Observado","En revisión")),IF(R7<0,"Vencido",IF(R7<=DiasAviso,"Por vencer","Por entregar"))) -> Vencido | T7: =IF(S7="Aprobado","Conforme"&IF(Q7<>""," desde el "&RIGHT("0"&DAY(Q7),2)&"/"&RIGHT("0"&MONTH(Q7),2)&"/"&YEAR(Q7),""),IF(S7="Observado",IF(P7="","Observado: registra la fecha de observación",IF(P7>=FechaRef,"Subsanar hasta el "&RIGHT("0"&DAY(P7),2)&"/"&RIGHT("0"&MONTH(P7),2)&"/"&YEAR(P7)&" (faltan "&(P7-FechaRef)&" días)","Plazo para subsanar vencido el "&RIGHT("0"&DAY(P7),2)&"/"&RIGHT("0"&MONTH(P7),2)&"/"&YEAR(P7))),IF(S7="En revisión",IF(M7<>"","Presentado el "&RIGHT("0"&DAY(M7),2)&"/"&RIGHT("0"&MONTH(M7),2)&"/"&YEAR(M7)&"; espera conformidad UGP/FAO","Entregado; espera conformidad UGP/FAO"),IF(R7<0,"Venció hace "&-R7&IF(R7=-1," día"," días"),IF(R7=0,"Vence hoy","Vence en "&R7&IF(R7=1," día"," días")))))) -> Venció hace 106 días | U7: =IF(L7<>"Sí","",IF(M7="","Sin fecha registrada",IF(M7<=H7,"A tiempo","Con "&(M7-H7)&" días de retraso"))) | V7: 180 | W7: =Inicio+V7 -> 46126 | X7: =F7-V7 -> 77 | Y7: el plan del piloto de recuperación | Z7: • Plan de recuperación y conectividad consensuado con CCNN y actas de aprobación. (*) • Fichas de caracterización de áreas de recuperación. • Informe de ejecución de los módulos 3 y 4 del plan «Tsimeeri». | AA7: =OR(FiltroEstado="Todos",S7=FiltroEstado) -> TRUE | AB7: =IF(AA7,COUNTIF($AA$5:AA7,TRUE()),"") -> 3 | AC7: =ROW()-4 -> 3 | AD7: =IF($S7=AD$4,COUNTIF($S$5:$S7,AD$4),"") | AE7: =IF($S7=AE$4,COUNTIF($S$5:$S7,AE$4),"") | AF7: =IF($S7=AF$4,COUNTIF($S$5:$S7,AF$4),"") -> 2 | AG7: =IF($S7=AG$4,COUNTIF($S$5:$S7,AG$4),"") | AH7: =IF($S7=AH$4,COUNTIF($S$5:$S7,AH$4),"") | AI7: =IF($S7=AI$4,COUNTIF($S$5:$S7,AI$4),"")
A8: P3 | B8: Producto 3 | D8: =B8&IF(C8="",""," · "&C8) -> Producto 3 | E8: Pasantía, plantaciones y planes de vida | F8: 428 | G8: =H7+1 -> 46204 | H8: =Inicio+F8 -> 46374 | I8: =F7+1 -> 258 | J8: 0.2 | K8: D3 | L8: No | P8: =IF(O8="","",O8+DiasSubsanar) | R8: =H8-FechaRef -> 65 | S8: =IF(L8="Sí",IF(N8="Conforme","Aprobado",IF(N8="Observado","Observado","En revisión")),IF(R8<0,"Vencido",IF(R8<=DiasAviso,"Por vencer","Por entregar"))) -> Por entregar | T8: =IF(S8="Aprobado","Conforme"&IF(Q8<>""," desde el "&RIGHT("0"&DAY(Q8),2)&"/"&RIGHT("0"&MONTH(Q8),2)&"/"&YEAR(Q8),""),IF(S8="Observado",IF(P8="","Observado: registra la fecha de observación",IF(P8>=FechaRef,"Subsanar hasta el "&RIGHT("0"&DAY(P8),2)&"/"&RIGHT("0"&MONTH(P8),2)&"/"&YEAR(P8)&" (faltan "&(P8-FechaRef)&" días)","Plazo para subsanar vencido el "&RIGHT("0"&DAY(P8),2)&"/"&RIGHT("0"&MONTH(P8),2)&"/"&YEAR(P8))),IF(S8="En revisión",IF(M8<>"","Presentado el "&RIGHT("0"&DAY(M8),2)&"/"&RIGHT("0"&MONTH(M8),2)&"/"&YEAR(M8)&"; espera conformidad UGP/FAO","Entregado; espera conformidad UGP/FAO"),IF(R8<0,"Venció hace "&-R8&IF(R8=-1," día"," días"),IF(R8=0,"Vence hoy","Vence en "&R8&IF(R8=1," día"," días")))))) -> Vence en 65 días | U8: =IF(L8<>"Sí","",IF(M8="","Sin fecha registrada",IF(M8<=H8,"A tiempo","Con "&(M8-H8)&" días de retraso"))) | V8: 360 | W8: =Inicio+V8 -> 46306 | X8: =F8-V8 -> 68 | Y8: el informe final de implementación de planes de vida | Z8: • Informe de pasantía en recuperación: aprendizajes, lecciones y hallazgos replicables. • Evaluación temprana de plantaciones según el modelo de recuperación seleccionado y adaptado. • Informe de avances en acciones de recuperación, por comunidad y paisaje. • Informe (final) de implementación de planes de vida, con enfoque de género. (*) | AA8: =OR(FiltroEstado="Todos",S8=FiltroEstado) -> TRUE | AB8: =IF(AA8,COUNTIF($AA$5:AA8,TRUE()),"") -> 4 | AC8: =ROW()-4 -> 4 | AD8: =IF($S8=AD$4,COUNTIF($S$5:$S8,AD$4),"") -> 1 | AE8: =IF($S8=AE$4,COUNTIF($S$5:$S8,AE$4),"") | AF8: =IF($S8=AF$4,COUNTIF($S$5:$S8,AF$4),"") | AG8: =IF($S8=AG$4,COUNTIF($S$5:$S8,AG$4),"") | AH8: =IF($S8=AH$4,COUNTIF($S$5:$S8,AH$4),"") | AI8: =IF($S8=AI$4,COUNTIF($S$5:$S8,AI$4),"")
A9: P4 | B9: Producto 4 | D9: =B9&IF(C9="",""," · "&C9) -> Producto 4 | E9: Informe final y resultados | F9: 561 | G9: =H8+1 -> 46375 | H9: =Inicio+F9 -> 46507 | I9: =F8+1 -> 429 | J9: 0.15 | K9: D4 | L9: No | P9: =IF(O9="","",O9+DiasSubsanar) | R9: =H9-FechaRef -> 198 | S9: =IF(L9="Sí",IF(N9="Conforme","Aprobado",IF(N9="Observado","Observado","En revisión")),IF(R9<0,"Vencido",IF(R9<=DiasAviso,"Por vencer","Por entregar"))) -> Por entregar | T9: =IF(S9="Aprobado","Conforme"&IF(Q9<>""," desde el "&RIGHT("0"&DAY(Q9),2)&"/"&RIGHT("0"&MONTH(Q9),2)&"/"&YEAR(Q9),""),IF(S9="Observado",IF(P9="","Observado: registra la fecha de observación",IF(P9>=FechaRef,"Subsanar hasta el "&RIGHT("0"&DAY(P9),2)&"/"&RIGHT("0"&MONTH(P9),2)&"/"&YEAR(P9)&" (faltan "&(P9-FechaRef)&" días)","Plazo para subsanar vencido el "&RIGHT("0"&DAY(P9),2)&"/"&RIGHT("0"&MONTH(P9),2)&"/"&YEAR(P9))),IF(S9="En revisión",IF(M9<>"","Presentado el "&RIGHT("0"&DAY(M9),2)&"/"&RIGHT("0"&MONTH(M9),2)&"/"&YEAR(M9)&"; espera conformidad UGP/FAO","Entregado; espera conformidad UGP/FAO"),IF(R9<0,"Venció hace "&-R9&IF(R9=-1," día"," días"),IF(R9=0,"Vence hoy","Vence en "&R9&IF(R9=1," día"," días")))))) -> Vence en 198 días | U9: =IF(L9<>"Sí","",IF(M9="","Sin fecha registrada",IF(M9<=H9,"A tiempo","Con "&(M9-H9)&" días de retraso"))) | V9: 540 | W9: =Inicio+V9 -> 46486 | X9: =F9-V9 -> 21 | Y9: el informe final del piloto (2,500 ha) y los resultados de capacitación | Z9: • Informe final de 2,500 hectáreas que iniciaron su proceso de recuperación. (*) • Fichas y matrices de monitoreo de la recuperación, con indicadores verificables. • Reporte de acciones y evidencias de monitoreo. • Evidencias de capacidades en recuperación fortalecidas en 60 líderes indígenas locales. (*) • Informe y evidencias de resultados e impactos de los 03 planes de vida. • Indicadores de resultados e impactos del enfoque de género. | AA9: =OR(FiltroEstado="Todos",S9=FiltroEstado) -> TRUE | AB9: =IF(AA9,COUNTIF($AA$5:AA9,TRUE()),"") -> 5 | AC9: =ROW()-4 -> 5 | AD9: =IF($S9=AD$4,COUNTIF($S$5:$S9,AD$4),"") -> 2 | AE9: =IF($S9=AE$4,COUNTIF($S$5:$S9,AE$4),"") | AF9: =IF($S9=AF$4,COUNTIF($S$5:$S9,AF$4),"") | AG9: =IF($S9=AG$4,COUNTIF($S$5:$S9,AG$4),"") | AH9: =IF($S9=AH$4,COUNTIF($S$5:$S9,AH$4),"") | AI9: =IF($S9=AI$4,COUNTIF($S$5:$S9,AI$4),"")
E10: Total | J10: =SUM(J5:J9) -> 1 | L10: =COUNTIF(L5:L9,"Sí")&" de "&ROWS(L5:L9) -> 1 de 5
A12: (*) Productos clave que requieren conformidad técnica de FAO (cláusula 8.2 y tabla 1 de la Adenda).
A13: Estado: Por entregar → Por vencer (faltan menos días que el aviso) → Vencido (pasó la fecha sin marcar «Sí»). Al marcar «Sí» pasa a En revisión; con la revisión «Observado» u «Conforme» cambia a Observado o Aprobado.
A14: Del Producto 1 solo hay constancia de su presentación el 30/11/2025 (Adenda, punto 1.4). Su conformidad no figura en los documentos: actualiza la columna N cuando la tengas.
A15: Columnas V a X: plazo del convenio original (cláusula 6) y prórroga que otorgó la Adenda. Columnas AA en adelante: auxiliares de los botones y filtros.

Sheet Desembolsos
B1: ← Volver al Panel
B2: Desembolsos y rendiciones (cláusula novena)
B3: Profonanpe transfiere en 4 pagos, previa opinión técnica, conformidades y rendición del pago anterior (cláusulas 9.1, 9.3 y 11.2). | O3: ▼ Edita O, P y Q
A4: N° | B4: Monto (S/) | C4: % del convenio | D4: % cláusula 9.1 | E4: Días según 9.1 | F4: Fecha según 9.1 | G4: Producto(s) que lo habilitan | H4: Código habilitante | I4: Fecha límite del producto (Adenda) | J4: Diferencia (días) | K4: ¿Producto presentado? | L4: ¿Producto aprobado? | M4: Rendición previa requerida | N4: ¿Rendición previa cumplida? | O4: ¿Desembolsado? | P4: Fecha de desembolso | Q4: Monto rendido por CARE (S/) | R4: % rendido | S4: Saldo por rendir (S/) | T4: Estado | U4: Siguiente paso | V4: Desembolsado (S/) | W4: Listo para solicitar (S/) | X4: Falta rendición (S/) | Y4: En conformidad (S/) | Z4: Pendiente de producto (S/) | AA4: Requisitos | AB4: Todos | AC4: Desembolsado | AD4: Listo para solicitar | AE4: Falta rendición | AF4: En conformidad | AG4: Pendiente de producto
A5: D1 | B5: 141375 | C5: =B5/TotalCARE -> 0.3 | D5: 0.3 | E5: 15 | F5: =IF(E5="","Al presentar P4",Inicio+E5) -> 45961 | G5: Producto 1 | H5: P1 | I5: =INDEX(Entregables!$H$5:$H$9,MATCH(H5,Entregables!$A$5:$A$9,0)) -> 46011 | J5: =IF(E5="",0,I5-F5) -> 50 | K5: =IF(Entregables!L5="Sí","Sí","No") -> Sí | L5: =IF(Entregables!S5="Aprobado","Sí","No") -> No | M5: ="No hay rendición previa: es el primer pago." -> No hay rendición previa: es el primer pago. | N5: ="Sí" -> Sí | O5: No | Q5: 0 | R5: =IF(O5="Sí",Q5/B5,"") | S5: =IF(O5="Sí",MAX(0,B5-Q5),0) -> 0 | T5: =IF(O5="Sí","Desembolsado",IF(K5="No","Pendiente de producto",IF(L5="No","En conformidad",IF(N5="Sí","Listo para solicitar","Falta rendición")))) -> En conformidad | U5: =IF(T5="Desembolsado","Pagado"&IF(P5<>""," el "&RIGHT("0"&DAY(P5),2)&"/"&RIGHT("0"&MONTH(P5),2)&"/"&YEAR(P5),"")&IF(S5>0,". Por rendir: S/ "&FIXED(S5,2),". Rendido al 100 %."),IF(T5="Pendiente de producto","Presentar "&G5&" (vence el "&RIGHT("0"&DAY(I5),2)&"/"&RIGHT("0"&MONTH(I5),2)&"/"&YEAR(I5)&")",IF(T5="En conformidad","Conseguir la opinión técnica del Componente 2 y las conformidades del Coordinador y de FAO",IF(T5="Falta rendición",M5,"La UGP debe pedir el desembolso por escrito a Profonanpe (cl. 9.3)")))) -> Conseguir la opinión técnica del Componente 2 y las conformidades del Coordinador y de FAO | V5: =IF($T5="Desembolsado",$B5,0) -> 0 | W5: =IF($T5="Listo para solicitar",$B5,0) -> 0 | X5: =IF($T5="Falta rendición",$B5,0) -> 0 | Y5: =IF($T5="En conformidad",$B5,0) -> 141375 | Z5: =IF($T5="Pendiente de producto",$B5,0) -> 0 | AA5: • Presentar el Producto 1. • Opinión técnica del Componente 2, conformidad del Coordinador Técnico y conformidad técnica de FAO. | AB5: =ROW()-4 -> 1 | AC5: =IF($T5=AC$4,COUNTIF($T$5:$T5,AC$4),"") | AD5: =IF($T5=AD$4,COUNTIF($T$5:$T5,AD$4),"") | AE5: =IF($T5=AE$4,COUNTIF($T$5:$T5,AE$4),"") | AF5: =IF($T5=AF$4,COUNTIF($T$5:$T5,AF$4),"") -> 1 | AG5: =IF($T5=AG$4,COUNTIF($T$5:$T5,AG$4),"")
A6: D2 | B6: 141375 | C6: =B6/TotalCARE -> 0.3 | D6: 0.3 | E6: 120 | F6: =IF(E6="","Al presentar P4",Inicio+E6) -> 46066 | G6: Producto 2 (Parte I y Parte II) | H6: P2-II | I6: =INDEX(Entregables!$H$5:$H$9,MATCH(H6,Entregables!$A$5:$A$9,0)) -> 46203 | J6: =IF(E6="",0,I6-F6) -> 137 | K6: =IF(AND(Entregables!L6="Sí",Entregables!L7="Sí"),"Sí","No") -> No | L6: =IF(AND(Entregables!S6="Aprobado",Entregables!S7="Aprobado"),"Sí","No") -> No | M6: ="Rendir al menos el "&TEXT(Rendicion*100,"0")&" % del 1.er desembolso: S/ "&FIXED(B5*Rendicion,2)&". Informe de recursos financiados." -> Rendir al menos el 70 % del 1.er desembolso: S/ 98,962.50. Informe de recursos financiados. | N6: =IF(Q5>=B5*Rendicion-0.005,"Sí","No") -> No | O6: No | Q6: 0 | R6: =IF(O6="Sí",Q6/B6,"") | S6: =IF(O6="Sí",MAX(0,B6-Q6),0) -> 0 | T6: =IF(O6="Sí","Desembolsado",IF(K6="No","Pendiente de producto",IF(L6="No","En conformidad",IF(N6="Sí","Listo para solicitar","Falta rendición")))) -> Pendiente de producto | U6: =IF(T6="Desembolsado","Pagado"&IF(P6<>""," el "&RIGHT("0"&DAY(P6),2)&"/"&RIGHT("0"&MONTH(P6),2)&"/"&YEAR(P6),"")&IF(S6>0,". Por rendir: S/ "&FIXED(S6,2),". Rendido al 100 %."),IF(T6="Pendiente de producto","Presentar "&G6&" (vence el "&RIGHT("0"&DAY(I6),2)&"/"&RIGHT("0"&MONTH(I6),2)&"/"&YEAR(I6)&")",IF(T6="En conformidad","Conseguir la opinión técnica del Componente 2 y las conformidades del Coordinador y de FAO",IF(T6="Falta rendición",M6,"La UGP debe pedir el desembolso por escrito a Profonanpe (cl. 9.3)")))) -> Presentar Producto 2 (Parte I y Parte II) (vence el 30/06/2026) | V6: =IF($T6="Desembolsado",$B6,0) -> 0 | W6: =IF($T6="Listo para solicitar",$B6,0) -> 0 | X6: =IF($T6="Falta rendición",$B6,0) -> 0 | Y6: =IF($T6="En conformidad",$B6,0) -> 0 | Z6: =IF($T6="Pendiente de producto",$B6,0) -> 141375 | AA6: • Presentar el Producto 2. • Conformidades técnicas (Componente 2, Coordinación y FAO). • Rendición ≥ 70 % del 1.er desembolso. • Informe de recursos financiados. | AB6: =ROW()-4 -> 2 | AC6: =IF($T6=AC$4,COUNTIF($T$5:$T6,AC$4),"") | AD6: =IF($T6=AD$4,COUNTIF($T$5:$T6,AD$4),"") | AE6: =IF($T6=AE$4,COUNTIF($T$5:$T6,AE$4),"") | AF6: =IF($T6=AF$4,COUNTIF($T$5:$T6,AF$4),"") | AG6: =IF($T6=AG$4,COUNTIF($T$5:$T6,AG$4),"") -> 1
A7: D3 | B7: 117812 | C7: =B7/TotalCARE -> 0.24999894 | D7: 0.25 | E7: 240 | F7: =IF(E7="","Al presentar P4",Inicio+E7) -> 46186 | G7: Producto 3 | H7: P3 | I7: =INDEX(Entregables!$H$5:$H$9,MATCH(H7,Entregables!$A$5:$A$9,0)) -> 46374 | J7: =IF(E7="",0,I7-F7) -> 188 | K7: =IF(Entregables!L8="Sí","Sí","No") -> No | L7: =IF(Entregables!S8="Aprobado","Sí","No") -> No | M7: ="Rendir el 100 % del 1.er desembolso (S/ "&FIXED(B5,2)&") y al menos el "&TEXT(Rendicion*100,"0")&" % del 2.º (S/ "&FIXED(B6*Rendicion,2)&"). Informe de recursos financiados." -> Rendir el 100 % del 1.er desembolso (S/ 141,375.00) y al menos el 70 % del 2.º (S/ 98,962.50). Informe de recursos financiados. | N7: =IF(AND(Q5>=B5-0.005,Q6>=B6*Rendicion-0.005),"Sí","No") -> No | O7: No | Q7: 0 | R7: =IF(O7="Sí",Q7/B7,"") | S7: =IF(O7="Sí",MAX(0,B7-Q7),0) -> 0 | T7: =IF(O7="Sí","Desembolsado",IF(K7="No","Pendiente de producto",IF(L7="No","En conformidad",IF(N7="Sí","Listo para solicitar","Falta rendición")))) -> Pendiente de producto | U7: =IF(T7="Desembolsado","Pagado"&IF(P7<>""," el "&RIGHT("0"&DAY(P7),2)&"/"&RIGHT("0"&MONTH(P7),2)&"/"&YEAR(P7),"")&IF(S7>0,". Por rendir: S/ "&FIXED(S7,2),". Rendido al 100 %."),IF(T7="Pendiente de producto","Presentar "&G7&" (vence el "&RIGHT("0"&DAY(I7),2)&"/"&RIGHT("0"&MONTH(I7),2)&"/"&YEAR(I7)&")",IF(T7="En conformidad","Conseguir la opinión técnica del Componente 2 y las conformidades del Coordinador y de FAO",IF(T7="Falta rendición",M7,"La UGP debe pedir el desembolso por escrito a Profonanpe (cl. 9.3)")))) -> Presentar Producto 3 (vence el 18/12/2026) | V7: =IF($T7="Desembolsado",$B7,0) -> 0 | W7: =IF($T7="Listo para solicitar",$B7,0) -> 0 | X7: =IF($T7="Falta rendición",$B7,0) -> 0 | Y7: =IF($T7="En conformidad",$B7,0) -> 0 | Z7: =IF($T7="Pendiente de producto",$B7,0) -> 117812 | AA7: • Presentar el Producto 3. • Conformidades técnicas (Componente 2, Coordinación y FAO). • Rendición del 30 % restante del 1.º y ≥ 70 % del 2.º. • Informe de recursos financiados. | AB7: =ROW()-4 -> 3 | AC7: =IF($T7=AC$4,COUNTIF($T$5:$T7,AC$4),"") | AD7: =IF($T7=AD$4,COUNTIF($T$5:$T7,AD$4),"") | AE7: =IF($T7=AE$4,COUNTIF($T$5:$T7,AE$4),"") | AF7: =IF($T7=AF$4,COUNTIF($T$5:$T7,AF$4),"") | AG7: =IF($T7=AG$4,COUNTIF($T$5:$T7,AG$4),"") -> 2
A8: D4 | B8: 70688 | C8: =B8/TotalCARE -> 0.15000106 | D8: 0.15 | F8: =IF(E8="","Al presentar P4",Inicio+E8) -> Al presentar P4 | G8: Producto 4 | H8: P4 | I8: =INDEX(Entregables!$H$5:$H$9,MATCH(H8,Entregables!$A$5:$A$9,0)) -> 46507 | J8: =IF(E8="",0,I8-F8) -> 0 | K8: =IF(Entregables!L9="Sí","Sí","No") -> No | L8: =IF(Entregables!S9="Aprobado","Sí","No") -> No | M8: ="Rendir el 100 % del 2.º desembolso (S/ "&FIXED(B6,2)&") y al menos el "&TEXT(Rendicion*100,"0")&" % del 3.º (S/ "&FIXED(B7*Rendicion,2)&"). Informe de recursos financiados o de contrapartida." -> Rendir el 100 % del 2.º desembolso (S/ 141,375.00) y al menos el 70 % del 3.º (S/ 82,468.40). Informe de recursos financiados o de contrapartida. | N8: =IF(AND(Q6>=B6-0.005,Q7>=B7*Rendicion-0.005),"Sí","No") -> No | O8: No | Q8: 0 | R8: =IF(O8="Sí",Q8/B8,"") | S8: =IF(O8="Sí",MAX(0,B8-Q8),0) -> 0 | T8: =IF(O8="Sí","Desembolsado",IF(K8="No","Pendiente de producto",IF(L8="No","En conformidad",IF(N8="Sí","Listo para solicitar","Falta rendición")))) -> Pendiente de producto | U8: =IF(T8="Desembolsado","Pagado"&IF(P8<>""," el "&RIGHT("0"&DAY(P8),2)&"/"&RIGHT("0"&MONTH(P8),2)&"/"&YEAR(P8),"")&IF(S8>0,". Por rendir: S/ "&FIXED(S8,2),". Rendido al 100 %."),IF(T8="Pendiente de producto","Presentar "&G8&" (vence el "&RIGHT("0"&DAY(I8),2)&"/"&RIGHT("0"&MONTH(I8),2)&"/"&YEAR(I8)&")",IF(T8="En conformidad","Conseguir la opinión técnica del Componente 2 y las conformidades del Coordinador y de FAO",IF(T8="Falta rendición",M8,"La UGP debe pedir el desembolso por escrito a Profonanpe (cl. 9.3)")))) -> Presentar Producto 4 (vence el 30/04/2027) | V8: =IF($T8="Desembolsado",$B8,0) -> 0 | W8: =IF($T8="Listo para solicitar",$B8,0) -> 0 | X8: =IF($T8="Falta rendición",$B8,0) -> 0 | Y8: =IF($T8="En conformidad",$B8,0) -> 0 | Z8: =IF($T8="Pendiente de producto",$B8,0) -> 70688 | AA8: • Presentar el Producto 4 (informe final). • Conformidades técnicas (Componente 2, Coordinación y FAO). • Rendición del 30 % restante del 2.º y ≥ 70 % del 3.º. • Informe de recursos financiados o de contrapartida. • El saldo del 4.º se rinde a más tardar 10 días después del informe final (cl. 9.2). | AB8: =ROW()-4 -> 4 | AC8: =IF($T8=AC$4,COUNTIF($T$5:$T8,AC$4),"") | AD8: =IF($T8=AD$4,COUNTIF($T$5:$T8,AD$4),"") | AE8: =IF($T8=AE$4,COUNTIF($T$5:$T8,AE$4),"") | AF8: =IF($T8=AF$4,COUNTIF($T$5:$T8,AF$4),"") | AG8: =IF($T8=AG$4,COUNTIF($T$5:$T8,AG$4),"") -> 3
A9: Total | B9: =SUM(B5:B8) -> 471250 | C9: =SUM(C5:C8) -> 1 | D9: =SUM(D5:D8) -> 1 | Q9: =SUM(Q5:Q8) -> 0 | S9: =SUM(S5:S8) -> 0 | V9: =SUM(V5:V8) -> 0 | W9: =SUM(W5:W8) -> 0 | X9: =SUM(X5:X8) -> 0 | Y9: =SUM(Y5:Y8) -> 141375 | Z9: =SUM(Z5:Z8) -> 329875
A11: ="Aparte, la UGP compra insumos y equipos por S/ "&FIXED(Parámetros!C9,2)&" que no se descuentan del convenio (cl. 9.1): tope total de Profonanpe S/ "&FIXED(Parámetros!C10,2)&" (cl. 5.2.1)." -> Aparte, la UGP compra insumos y equipos por S/ 40,000.00 que no se descuentan del convenio (cl. 9.1): tope total de Profonanpe S/ 511,250.00 (cl. 5.2.1).
A12: La «fecha según 9.1» es la del convenio original y no fue actualizada por la Adenda: hoy cae antes del producto que habilita cada pago. En la práctica el pago llega tras presentar el producto y reunir conformidades.
A13: Estado: Pendiente de producto → En conformidad (producto presentado, falta aprobación) → Falta rendición (aprobado, pero no se cumple la rendición previa) → Listo para solicitar → Desembolsado.
A14: Se asume que el Desembolso 2 requiere las dos partes del Producto 2 (punto por aclarar con Profonanpe, ver hoja Dudas).

Sheet Vistas
B1: ← Volver al Panel
B2: Vistas por estado
B3: Destino de los botones del Panel. Cada bloque lista los productos o desembolsos en ese estado, según la fecha de referencia.
B4: Índice
B5: Productos: | C5: Todos | D5: Por entregar | E5: Por vencer | F5: Vencido | G5: En revisión | H5: Observado | I5: Aprobado
B7: Desembolsos: | C7: Todos | D7: Desembolsado | E7: Listo para solicitar | F7: Falta rendición | G7: En conformidad | H7: Pendiente de producto
B10: ="PRODUCTOS · TODOS LOS PRODUCTOS ("&5&")" -> PRODUCTOS · TODOS LOS PRODUCTOS (5) | H10: ↑ Índice | I10: ← Panel
B11: Producto | C11: Título | D11: Fecha límite | E11: Días restantes | F11: Estado | G11: Situación | H11: Desembolso | I11: Fecha de entrega
B12: =IFERROR(INDEX(Entregables!$D$5:$D$9,MATCH(1,Entregables!$AC$5:$AC$9,0)),"") -> Producto 1 | C12: =IFERROR(INDEX(Entregables!$E$5:$E$9,MATCH(1,Entregables!$AC$5:$AC$9,0)),"") -> Plan de trabajo y cronograma | D12: =IFERROR(INDEX(Entregables!$H$5:$H$9,MATCH(1,Entregables!$AC$5:$AC$9,0)),"") -> 46011 | E12: =IFERROR(INDEX(Entregables!$R$5:$R$9,MATCH(1,Entregables!$AC$5:$AC$9,0)),"") -> -298 | F12: =IFERROR(INDEX(Entregables!$S$5:$S$9,MATCH(1,Entregables!$AC$5:$AC$9,0)),"") -> En revisión | G12: =IFERROR(INDEX(Entregables!$T$5:$T$9,MATCH(1,Entregables!$AC$5:$AC$9,0)),"") -> Presentado el 30/11/2025; espera conformidad UGP/FAO | H12: =IFERROR(INDEX(Entregables!$K$5:$K$9,MATCH(1,Entregables!$AC$5:$AC$9,0)),"") -> D1 | I12: =IFERROR(IF(INDEX(Entregables!$M$5:$M$9,MATCH(1,Entregables!$AC$5:$AC$9,0))="","",INDEX(Entregables!$M$5:$M$9,MATCH(1,Entregables!$AC$5:$AC$9,0))),"") -> 45991
B13: =IFERROR(INDEX(Entregables!$D$5:$D$9,MATCH(2,Entregables!$AC$5:$AC$9,0)),"") -> Producto 2 · Parte I | C13: =IFERROR(INDEX(Entregables!$E$5:$E$9,MATCH(2,Entregables!$AC$5:$AC$9,0)),"") -> Plan de capacitación y avances | D13: =IFERROR(INDEX(Entregables!$H$5:$H$9,MATCH(2,Entregables!$AC$5:$AC$9,0)),"") -> 46142 | E13: =IFERROR(INDEX(Entregables!$R$5:$R$9,MATCH(2,Entregables!$AC$5:$AC$9,0)),"") -> -167 | F13: =IFERROR(INDEX(Entregables!$S$5:$S$9,MATCH(2,Entregables!$AC$5:$AC$9,0)),"") -> Vencido | G13: =IFERROR(INDEX(Entregables!$T$5:$T$9,MATCH(2,Entregables!$AC$5:$AC$9,0)),"") -> Venció hace 167 días | H13: =IFERROR(INDEX(Entregables!$K$5:$K$9,MATCH(2,Entregables!$AC$5:$AC$9,0)),"") -> D2 | I13: =IFERROR(IF(INDEX(Entregables!$M$5:$M$9,MATCH(2,Entregables!$AC$5:$AC$9,0))="","",INDEX(Entregables!$M$5:$M$9,MATCH(2,Entregables!$AC$5:$AC$9,0))),"")
B14: =IFERROR(INDEX(Entregables!$D$5:$D$9,MATCH(3,Entregables!$AC$5:$AC$9,0)),"") -> Producto 2 · Parte II | C14: =IFERROR(INDEX(Entregables!$E$5:$E$9,MATCH(3,Entregables!$AC$5:$AC$9,0)),"") -> Plan de recuperación y fichas | D14: =IFERROR(INDEX(Entregables!$H$5:$H$9,MATCH(3,Entregables!$AC$5:$AC$9,0)),"") -> 46203 | E14: =IFERROR(INDEX(Entregables!$R$5:$R$9,MATCH(3,Entregables!$AC$5:$AC$9,0)),"") -> -106 | F14: =IFERROR(INDEX(Entregables!$S$5:$S$9,MATCH(3,Entregables!$AC$5:$AC$9,0)),"") -> Vencido | G14: =IFERROR(INDEX(Entregables!$T$5:$T$9,MATCH(3,Entregables!$AC$5:$AC$9,0)),"") -> Venció hace 106 días | H14: =IFERROR(INDEX(Entregables!$K$5:$K$9,MATCH(3,Entregables!$AC$5:$AC$9,0)),"") -> D2 | I14: =IFERROR(IF(INDEX(Entregables!$M$5:$M$9,MATCH(3,Entregables!$AC$5:$AC$9,0))="","",INDEX(Entregables!$M$5:$M$9,MATCH(3,Entregables!$AC$5:$AC$9,0))),"")
B15: =IFERROR(INDEX(Entregables!$D$5:$D$9,MATCH(4,Entregables!$AC$5:$AC$9,0)),"") -> Producto 3 | C15: =IFERROR(INDEX(Entregables!$E$5:$E$9,MATCH(4,Entregables!$AC$5:$AC$9,0)),"") -> Pasantía, plantaciones y planes de vida | D15: =IFERROR(INDEX(Entregables!$H$5:$H$9,MATCH(4,Entregables!$AC$5:$AC$9,0)),"") -> 46374 | E15: =IFERROR(INDEX(Entregables!$R$5:$R$9,MATCH(4,Entregables!$AC$5:$AC$9,0)),"") -> 65 | F15: =IFERROR(INDEX(Entregables!$S$5:$S$9,MATCH(4,Entregables!$AC$5:$AC$9,0)),"") -> Por entregar | G15: =IFERROR(INDEX(Entregables!$T$5:$T$9,MATCH(4,Entregables!$AC$5:$AC$9,0)),"") -> Vence en 65 días | H15: =IFERROR(INDEX(Entregables!$K$5:$K$9,MATCH(4,Entregables!$AC$5:$AC$9,0)),"") -> D3 | I15: =IFERROR(IF(INDEX(Entregables!$M$5:$M$9,MATCH(4,Entregables!$AC$5:$AC$9,0))="","",INDEX(Entregables!$M$5:$M$9,MATCH(4,Entregables!$AC$5:$AC$9,0))),"")
B16: =IFERROR(INDEX(Entregables!$D$5:$D$9,MATCH(5,Entregables!$AC$5:$AC$9,0)),"") -> Producto 4 | C16: =IFERROR(INDEX(Entregables!$E$5:$E$9,MATCH(5,Entregables!$AC$5:$AC$9,0)),"") -> Informe final y resultados | D16: =IFERROR(INDEX(Entregables!$H$5:$H$9,MATCH(5,Entregables!$AC$5:$AC$9,0)),"") -> 46507 | E16: =IFERROR(INDEX(Entregables!$R$5:$R$9,MATCH(5,Entregables!$AC$5:$AC$9,0)),"") -> 198 | F16: =IFERROR(INDEX(Entregables!$S$5:$S$9,MATCH(5,Entregables!$AC$5:$AC$9,0)),"") -> Por entregar | G16: =IFERROR(INDEX(Entregables!$T$5:$T$9,MATCH(5,Entregables!$AC$5:$AC$9,0)),"") -> Vence en 198 días | H16: =IFERROR(INDEX(Entregables!$K$5:$K$9,MATCH(5,Entregables!$AC$5:$AC$9,0)),"") -> D4 | I16: =IFERROR(IF(INDEX(Entregables!$M$5:$M$9,MATCH(5,Entregables!$AC$5:$AC$9,0))="","",INDEX(Entregables!$M$5:$M$9,MATCH(5,Entregables!$AC$5:$AC$9,0))),"")
B18: ="PRODUCTOS · POR ENTREGAR ("&'Datos gráficos'!$C$27&")" -> PRODUCTOS · POR ENTREGAR (2) | H18: ↑ Índice | I18: ← Panel
B19: Producto | C19: Título | D19: Fecha límite | E19: Días restantes | F19: Estado | G19: Situación | H19: Desembolso | I19: Fecha de entrega
B20: =IFERROR(INDEX(Entregables!$D$5:$D$9,MATCH(1,Entregables!$AD$5:$AD$9,0)),"Ningún producto en este estado.") -> Producto 3 | C20: =IFERROR(INDEX(Entregables!$E$5:$E$9,MATCH(1,Entregables!$AD$5:$AD$9,0)),"") -> Pasantía, plantaciones y planes de vida | D20: =IFERROR(INDEX(Entregables!$H$5:$H$9,MATCH(1,Entregables!$AD$5:$AD$9,0)),"") -> 46374 | E20: =IFERROR(INDEX(Entregables!$R$5:$R$9,MATCH(1,Entregables!$AD$5:$AD$9,0)),"") -> 65 | F20: =IFERROR(INDEX(Entregables!$S$5:$S$9,MATCH(1,Entregables!$AD$5:$AD$9,0)),"") -> Por entregar | G20: =IFERROR(INDEX(Entregables!$T$5:$T$9,MATCH(1,Entregables!$AD$5:$AD$9,0)),"") -> Vence en 65 días | H20: =IFERROR(INDEX(Entregables!$K$5:$K$9,MATCH(1,Entregables!$AD$5:$AD$9,0)),"") -> D3 | I20: =IFERROR(IF(INDEX(Entregables!$M$5:$M$9,MATCH(1,Entregables!$AD$5:$AD$9,0))="","",INDEX(Entregables!$M$5:$M$9,MATCH(1,Entregables!$AD$5:$AD$9,0))),"")
B21: =IFERROR(INDEX(Entregables!$D$5:$D$9,MATCH(2,Entregables!$AD$5:$AD$9,0)),"") -> Producto 4 | C21: =IFERROR(INDEX(Entregables!$E$5:$E$9,MATCH(2,Entregables!$AD$5:$AD$9,0)),"") -> Informe final y resultados | D21: =IFERROR(INDEX(Entregables!$H$5:$H$9,MATCH(2,Entregables!$AD$5:$AD$9,0)),"") -> 46507 | E21: =IFERROR(INDEX(Entregables!$R$5:$R$9,MATCH(2,Entregables!$AD$5:$AD$9,0)),"") -> 198 | F21: =IFERROR(INDEX(Entregables!$S$5:$S$9,MATCH(2,Entregables!$AD$5:$AD$9,0)),"") -> Por entregar | G21: =IFERROR(INDEX(Entregables!$T$5:$T$9,MATCH(2,Entregables!$AD$5:$AD$9,0)),"") -> Vence en 198 días | H21: =IFERROR(INDEX(Entregables!$K$5:$K$9,MATCH(2,Entregables!$AD$5:$AD$9,0)),"") -> D4 | I21: =IFERROR(IF(INDEX(Entregables!$M$5:$M$9,MATCH(2,Entregables!$AD$5:$AD$9,0))="","",INDEX(Entregables!$M$5:$M$9,MATCH(2,Entregables!$AD$5:$AD$9,0))),"")
B22: =IFERROR(INDEX(Entregables!$D$5:$D$9,MATCH(3,Entregables!$AD$5:$AD$9,0)),"") | C22: =IFERROR(INDEX(Entregables!$E$5:$E$9,MATCH(3,Entregables!$AD$5:$AD$9,0)),"") | D22: =IFERROR(INDEX(Entregables!$H$5:$H$9,MATCH(3,Entregables!$AD$5:$AD$9,0)),"") | E22: =IFERROR(INDEX(Entregables!$R$5:$R$9,MATCH(3,Entregables!$AD$5:$AD$9,0)),"") | F22: =IFERROR(INDEX(Entregables!$S$5:$S$9,MATCH(3,Entregables!$AD$5:$AD$9,0)),"") | G22: =IFERROR(INDEX(Entregables!$T$5:$T$9,MATCH(3,Entregables!$AD$5:$AD$9,0)),"") | H22: =IFERROR(INDEX(Entregables!$K$5:$K$9,MATCH(3,Entregables!$AD$5:$AD$9,0)),"") | I22: =IFERROR(IF(INDEX(Entregables!$M$5:$M$9,MATCH(3,Entregables!$AD$5:$AD$9,0))="","",INDEX(Entregables!$M$5:$M$9,MATCH(3,Entregables!$AD$5:$AD$9,0))),"")
B23: =IFERROR(INDEX(Entregables!$D$5:$D$9,MATCH(4,Entregables!$AD$5:$AD$9,0)),"") | C23: =IFERROR(INDEX(Entregables!$E$5:$E$9,MATCH(4,Entregables!$AD$5:$AD$9,0)),"") | D23: =IFERROR(INDEX(Entregables!$H$5:$H$9,MATCH(4,Entregables!$AD$5:$AD$9,0)),"") | E23: =IFERROR(INDEX(Entregables!$R$5:$R$9,MATCH(4,Entregables!$AD$5:$AD$9,0)),"") | F23: =IFERROR(INDEX(Entregables!$S$5:$S$9,MATCH(4,Entregables!$AD$5:$AD$9,0)),"") | G23: =IFERROR(INDEX(Entregables!$T$5:$T$9,MATCH(4,Entregables!$AD$5:$AD$9,0)),"") | H23: =IFERROR(INDEX(Entregables!$K$5:$K$9,MATCH(4,Entregables!$AD$5:$AD$9,0)),"") | I23: =IFERROR(IF(INDEX(Entregables!$M$5:$M$9,MATCH(4,Entregables!$AD$5:$AD$9,0))="","",INDEX(Entregables!$M$5:$M$9,MATCH(4,Entregables!$AD$5:$AD$9,0))),"")
B24: =IFERROR(INDEX(Entregables!$D$5:$D$9,MATCH(5,Entregables!$AD$5:$AD$9,0)),"") | C24: =IFERROR(INDEX(Entregables!$E$5:$E$9,MATCH(5,Entregables!$AD$5:$AD$9,0)),"") | D24: =IFERROR(INDEX(Entregables!$H$5:$H$9,MATCH(5,Entregables!$AD$5:$AD$9,0)),"") | E24: =IFERROR(INDEX(Entregables!$R$5:$R$9,MATCH(5,Entregables!$AD$5:$AD$9,0)),"") | F24: =IFERROR(INDEX(Entregables!$S$5:$S$9,MATCH(5,Entregables!$AD$5:$AD$9,0)),"") | G24: =IFERROR(INDEX(Entregables!$T$5:$T$9,MATCH(5,Entregables!$AD$5:$AD$9,0)),"") | H24: =IFERROR(INDEX(Entregables!$K$5:$K$9,MATCH(5,Entregables!$AD$5:$AD$9,0)),"") | I24: =IFERROR(IF(INDEX(Entregables!$M$5:$M$9,MATCH(5,Entregables!$AD$5:$AD$9,0))="","",INDEX(Entregables!$M$5:$M$9,MATCH(5,Entregables!$AD$5:$AD$9,0))),"")
B26: ="PRODUCTOS · POR VENCER ("&'Datos gráficos'!$C$28&")" -> PRODUCTOS · POR VENCER (0) | H26: ↑ Índice | I26: ← Panel
B27: Producto | C27: Título | D27: Fecha límite | E27: Días restantes | F27: Estado | G27: Situación | H27: Desembolso | I27: Fecha de entrega
B28: =IFERROR(INDEX(Entregables!$D$5:$D$9,MATCH(1,Entregables!$AE$5:$AE$9,0)),"Ningún producto en este estado.") -> Ningún producto en este estado. | C28: =IFERROR(INDEX(Entregables!$E$5:$E$9,MATCH(1,Entregables!$AE$5:$AE$9,0)),"") | D28: =IFERROR(INDEX(Entregables!$H$5:$H$9,MATCH(1,Entregables!$AE$5:$AE$9,0)),"") | E28: =IFERROR(INDEX(Entregables!$R$5:$R$9,MATCH(1,Entregables!$AE$5:$AE$9,0)),"") | F28: =IFERROR(INDEX(Entregables!$S$5:$S$9,MATCH(1,Entregables!$AE$5:$AE$9,0)),"") | G28: =IFERROR(INDEX(Entregables!$T$5:$T$9,MATCH(1,Entregables!$AE$5:$AE$9,0)),"") | H28: =IFERROR(INDEX(Entregables!$K$5:$K$9,MATCH(1,Entregables!$AE$5:$AE$9,0)),"") | I28: =IFERROR(IF(INDEX(Entregables!$M$5:$M$9,MATCH(1,Entregables!$AE$5:$AE$9,0))="","",INDEX(Entregables!$M$5:$M$9,MATCH(1,Entregables!$AE$5:$AE$9,0))),"")
B29: =IFERROR(INDEX(Entregables!$D$5:$D$9,MATCH(2,Entregables!$AE$5:$AE$9,0)),"") | C29: =IFERROR(INDEX(Entregables!$E$5:$E$9,MATCH(2,Entregables!$AE$5:$AE$9,0)),"") | D29: =IFERROR(INDEX(Entregables!$H$5:$H$9,MATCH(2,Entregables!$AE$5:$AE$9,0)),"") | E29: =IFERROR(INDEX(Entregables!$R$5:$R$9,MATCH(2,Entregables!$AE$5:$AE$9,0)),"") | F29: =IFERROR(INDEX(Entregables!$S$5:$S$9,MATCH(2,Entregables!$AE$5:$AE$9,0)),"") | G29: =IFERROR(INDEX(Entregables!$T$5:$T$9,MATCH(2,Entregables!$AE$5:$AE$9,0)),"") | H29: =IFERROR(INDEX(Entregables!$K$5:$K$9,MATCH(2,Entregables!$AE$5:$AE$9,0)),"") | I29: =IFERROR(IF(INDEX(Entregables!$M$5:$M$9,MATCH(2,Entregables!$AE$5:$AE$9,0))="","",INDEX(Entregables!$M$5:$M$9,MATCH(2,Entregables!$AE$5:$AE$9,0))),"")
B30: =IFERROR(INDEX(Entregables!$D$5:$D$9,MATCH(3,Entregables!$AE$5:$AE$9,0)),"") | C30: =IFERROR(INDEX(Entregables!$E$5:$E$9,MATCH(3,Entregables!$AE$5:$AE$9,0)),"") | D30: =IFERROR(INDEX(Entregables!$H$5:$H$9,MATCH(3,Entregables!$AE$5:$AE$9,0)),"") | E30: =IFERROR(INDEX(Entregables!$R$5:$R$9,MATCH(3,Entregables!$AE$5:$AE$9,0)),"") | F30: =IFERROR(INDEX(Entregables!$S$5:$S$9,MATCH(3,Entregables!$AE$5:$AE$9,0)),"") | G30: =IFERROR(INDEX(Entregables!$T$5:$T$9,MATCH(3,Entregables!$AE$5:$AE$9,0)),"") | H30: =IFERROR(INDEX(Entregables!$K$5:$K$9,MATCH(3,Entregables!$AE$5:$AE$9,0)),"") | I30: =IFERROR(IF(INDEX(Entregables!$M$5:$M$9,MATCH(3,Entregables!$AE$5:$AE$9,0))="","",INDEX(Entregables!$M$5:$M$9,MATCH(3,Entregables!$AE$5:$AE$9,0))),"")
B31: =IFERROR(INDEX(Entregables!$D$5:$D$9,MATCH(4,Entregables!$AE$5:$AE$9,0)),"") | C31: =IFERROR(INDEX(Entregables!$E$5:$E$9,MATCH(4,Entregables!$AE$5:$AE$9,0)),"") | D31: =IFERROR(INDEX(Entregables!$H$5:$H$9,MATCH(4,Entregables!$AE$5:$AE$9,0)),"") | E31: =IFERROR(INDEX(Entregables!$R$5:$R$9,MATCH(4,Entregables!$AE$5:$AE$9,0)),"") | F31: =IFERROR(INDEX(Entregables!$S$5:$S$9,MATCH(4,Entregables!$AE$5:$AE$9,0)),"") | G31: =IFERROR(INDEX(Entregables!$T$5:$T$9,MATCH(4,Entregables!$AE$5:$AE$9,0)),"") | H31: =IFERROR(INDEX(Entregables!$K$5:$K$9,MATCH(4,Entregables!$AE$5:$AE$9,0)),"") | I31: =IFERROR(IF(INDEX(Entregables!$M$5:$M$9,MATCH(4,Entregables!$AE$5:$AE$9,0))="","",INDEX(Entregables!$M$5:$M$9,MATCH(4,Entregables!$AE$5:$AE$9,0))),"")
B32: =IFERROR(INDEX(Entregables!$D$5:$D$9,MATCH(5,Entregables!$AE$5:$AE$9,0)),"") | C32: =IFERROR(INDEX(Entregables!$E$5:$E$9,MATCH(5,Entregables!$AE$5:$AE$9,0)),"") | D32: =IFERROR(INDEX(Entregables!$H$5:$H$9,MATCH(5,Entregables!$AE$5:$AE$9,0)),"") | E32: =IFERROR(INDEX(Entregables!$R$5:$R$9,MATCH(5,Entregables!$AE$5:$AE$9,0)),"") | F32: =IFERROR(INDEX(Entregables!$S$5:$S$9,MATCH(5,Entregables!$AE$5:$AE$9,0)),"") | G32: =IFERROR(INDEX(Entregables!$T$5:$T$9,MATCH(5,Entregables!$AE$5:$AE$9,0)),"") | H32: =IFERROR(INDEX(Entregables!$K$5:$K$9,MATCH(5,Entregables!$AE$5:$AE$9,0)),"") | I32: =IFERROR(IF(INDEX(Entregables!$M$5:$M$9,MATCH(5,Entregables!$AE$5:$AE$9,0))="","",INDEX(Entregables!$M$5:$M$9,MATCH(5,Entregables!$AE$5:$AE$9,0))),"")
B34: ="PRODUCTOS · VENCIDO ("&'Datos gráficos'!$C$29&")" -> PRODUCTOS · VENCIDO (2) | H34: ↑ Índice | I34: ← Panel
B35: Producto | C35: Título | D35: Fecha límite | E35: Días restantes | F35: Estado | G35: Situación | H35: Desembolso | I35: Fecha de entrega
B36: =IFERROR(INDEX(Entregables!$D$5:$D$9,MATCH(1,Entregables!$AF$5:$AF$9,0)),"Ningún producto en este estado.") -> Producto 2 · Parte I | C36: =IFERROR(INDEX(Entregables!$E$5:$E$9,MATCH(1,Entregables!$AF$5:$AF$9,0)),"") -> Plan de capacitación y avances | D36: =IFERROR(INDEX(Entregables!$H$5:$H$9,MATCH(1,Entregables!$AF$5:$AF$9,0)),"") -> 46142 | E36: =IFERROR(INDEX(Entregables!$R$5:$R$9,MATCH(1,Entregables!$AF$5:$AF$9,0)),"") -> -167 | F36: =IFERROR(INDEX(Entregables!$S$5:$S$9,MATCH(1,Entregables!$AF$5:$AF$9,0)),"") -> Vencido | G36: =IFERROR(INDEX(Entregables!$T$5:$T$9,MATCH(1,Entregables!$AF$5:$AF$9,0)),"") -> Venció hace 167 días | H36: =IFERROR(INDEX(Entregables!$K$5:$K$9,MATCH(1,Entregables!$AF$5:$AF$9,0)),"") -> D2 | I36: =IFERROR(IF(INDEX(Entregables!$M$5:$M$9,MATCH(1,Entregables!$AF$5:$AF$9,0))="","",INDEX(Entregables!$M$5:$M$9,MATCH(1,Entregables!$AF$5:$AF$9,0))),"")
B37: =IFERROR(INDEX(Entregables!$D$5:$D$9,MATCH(2,Entregables!$AF$5:$AF$9,0)),"") -> Producto 2 · Parte II | C37: =IFERROR(INDEX(Entregables!$E$5:$E$9,MATCH(2,Entregables!$AF$5:$AF$9,0)),"") -> Plan de recuperación y fichas | D37: =IFERROR(INDEX(Entregables!$H$5:$H$9,MATCH(2,Entregables!$AF$5:$AF$9,0)),"") -> 46203 | E37: =IFERROR(INDEX(Entregables!$R$5:$R$9,MATCH(2,Entregables!$AF$5:$AF$9,0)),"") -> -106 | F37: =IFERROR(INDEX(Entregables!$S$5:$S$9,MATCH(2,Entregables!$AF$5:$AF$9,0)),"") -> Vencido | G37: =IFERROR(INDEX(Entregables!$T$5:$T$9,MATCH(2,Entregables!$AF$5:$AF$9,0)),"") -> Venció hace 106 días | H37: =IFERROR(INDEX(Entregables!$K$5:$K$9,MATCH(2,Entregables!$AF$5:$AF$9,0)),"") -> D2 | I37: =IFERROR(IF(INDEX(Entregables!$M$5:$M$9,MATCH(2,Entregables!$AF$5:$AF$9,0))="","",INDEX(Entregables!$M$5:$M$9,MATCH(2,Entregables!$AF$5:$AF$9,0))),"")
B38: =IFERROR(INDEX(Entregables!$D$5:$D$9,MATCH(3,Entregables!$AF$5:$AF$9,0)),"") | C38: =IFERROR(INDEX(Entregables!$E$5:$E$9,MATCH(3,Entregables!$AF$5:$AF$9,0)),"") | D38: =IFERROR(INDEX(Entregables!$H$5:$H$9,MATCH(3,Entregables!$AF$5:$AF$9,0)),"") | E38: =IFERROR(INDEX(Entregables!$R$5:$R$9,MATCH(3,Entregables!$AF$5:$AF$9,0)),"") | F38: =IFERROR(INDEX(Entregables!$S$5:$S$9,MATCH(3,Entregables!$AF$5:$AF$9,0)),"") | G38: =IFERROR(INDEX(Entregables!$T$5:$T$9,MATCH(3,Entregables!$AF$5:$AF$9,0)),"") | H38: =IFERROR(INDEX(Entregables!$K$5:$K$9,MATCH(3,Entregables!$AF$5:$AF$9,0)),"") | I38: =IFERROR(IF(INDEX(Entregables!$M$5:$M$9,MATCH(3,Entregables!$AF$5:$AF$9,0))="","",INDEX(Entregables!$M$5:$M$9,MATCH(3,Entregables!$AF$5:$AF$9,0))),"")
B39: =IFERROR(INDEX(Entregables!$D$5:$D$9,MATCH(4,Entregables!$AF$5:$AF$9,0)),"") | C39: =IFERROR(INDEX(Entregables!$E$5:$E$9,MATCH(4,Entregables!$AF$5:$AF$9,0)),"") | D39: =IFERROR(INDEX(Entregables!$H$5:$H$9,MATCH(4,Entregables!$AF$5:$AF$9,0)),"") | E39: =IFERROR(INDEX(Entregables!$R$5:$R$9,MATCH(4,Entregables!$AF$5:$AF$9,0)),"") | F39: =IFERROR(INDEX(Entregables!$S$5:$S$9,MATCH(4,Entregables!$AF$5:$AF$9,0)),"") | G39: =IFERROR(INDEX(Entregables!$T$5:$T$9,MATCH(4,Entregables!$AF$5:$AF$9,0)),"") | H39: =IFERROR(INDEX(Entregables!$K$5:$K$9,MATCH(4,Entregables!$AF$5:$AF$9,0)),"") | I39: =IFERROR(IF(INDEX(Entregables!$M$5:$M$9,MATCH(4,Entregables!$AF$5:$AF$9,0))="","",INDEX(Entregables!$M$5:$M$9,MATCH(4,Entregables!$AF$5:$AF$9,0))),"")
B40: =IFERROR(INDEX(Entregables!$D$5:$D$9,MATCH(5,Entregables!$AF$5:$AF$9,0)),"") | C40: =IFERROR(INDEX(Entregables!$E$5:$E$9,MATCH(5,Entregables!$AF$5:$AF$9,0)),"") | D40: =IFERROR(INDEX(Entregables!$H$5:$H$9,MATCH(5,Entregables!$AF$5:$AF$9,0)),"") | E40: =IFERROR(INDEX(Entregables!$R$5:$R$9,MATCH(5,Entregables!$AF$5:$AF$9,0)),"") | F40: =IFERROR(INDEX(Entregables!$S$5:$S$9,MATCH(5,Entregables!$AF$5:$AF$9,0)),"") | G40: =IFERROR(INDEX(Entregables!$T$5:$T$9,MATCH(5,Entregables!$AF$5:$AF$9,0)),"") | H40: =IFERROR(INDEX(Entregables!$K$5:$K$9,MATCH(5,Entregables!$AF$5:$AF$9,0)),"") | I40: =IFERROR(IF(INDEX(Entregables!$M$5:$M$9,MATCH(5,Entregables!$AF$5:$AF$9,0))="","",INDEX(Entregables!$M$5:$M$9,MATCH(5,Entregables!$AF$5:$AF$9,0))),"")
B42: ="PRODUCTOS · EN REVISIÓN ("&'Datos gráficos'!$C$30&")" -> PRODUCTOS · EN REVISIÓN (1) | H42: ↑ Índice | I42: ← Panel
B43: Producto | C43: Título | D43: Fecha límite | E43: Días restantes | F43: Estado | G43: Situación | H43: Desembolso | I43: Fecha de entrega
B44: =IFERROR(INDEX(Entregables!$D$5:$D$9,MATCH(1,Entregables!$AG$5:$AG$9,0)),"Ningún producto en este estado.") -> Producto 1 | C44: =IFERROR(INDEX(Entregables!$E$5:$E$9,MATCH(1,Entregables!$AG$5:$AG$9,0)),"") -> Plan de trabajo y cronograma | D44: =IFERROR(INDEX(Entregables!$H$5:$H$9,MATCH(1,Entregables!$AG$5:$AG$9,0)),"") -> 46011 | E44: =IFERROR(INDEX(Entregables!$R$5:$R$9,MATCH(1,Entregables!$AG$5:$AG$9,0)),"") -> -298 | F44: =IFERROR(INDEX(Entregables!$S$5:$S$9,MATCH(1,Entregables!$AG$5:$AG$9,0)),"") -> En revisión | G44: =IFERROR(INDEX(Entregables!$T$5:$T$9,MATCH(1,Entregables!$AG$5:$AG$9,0)),"") -> Presentado el 30/11/2025; espera conformidad UGP/FAO | H44: =IFERROR(INDEX(Entregables!$K$5:$K$9,MATCH(1,Entregables!$AG$5:$AG$9,0)),"") -> D1 | I44: =IFERROR(IF(INDEX(Entregables!$M$5:$M$9,MATCH(1,Entregables!$AG$5:$AG$9,0))="","",INDEX(Entregables!$M$5:$M$9,MATCH(1,Entregables!$AG$5:$AG$9,0))),"") -> 45991
B45: =IFERROR(INDEX(Entregables!$D$5:$D$9,MATCH(2,Entregables!$AG$5:$AG$9,0)),"") | C45: =IFERROR(INDEX(Entregables!$E$5:$E$9,MATCH(2,Entregables!$AG$5:$AG$9,0)),"") | D45: =IFERROR(INDEX(Entregables!$H$5:$H$9,MATCH(2,Entregables!$AG$5:$AG$9,0)),"") | E45: =IFERROR(INDEX(Entregables!$R$5:$R$9,MATCH(2,Entregables!$AG$5:$AG$9,0)),"") | F45: =IFERROR(INDEX(Entregables!$S$5:$S$9,MATCH(2,Entregables!$AG$5:$AG$9,0)),"") | G45: =IFERROR(INDEX(Entregables!$T$5:$T$9,MATCH(2,Entregables!$AG$5:$AG$9,0)),"") | H45: =IFERROR(INDEX(Entregables!$K$5:$K$9,MATCH(2,Entregables!$AG$5:$AG$9,0)),"") | I45: =IFERROR(IF(INDEX(Entregables!$M$5:$M$9,MATCH(2,Entregables!$AG$5:$AG$9,0))="","",INDEX(Entregables!$M$5:$M$9,MATCH(2,Entregables!$AG$5:$AG$9,0))),"")
B46: =IFERROR(INDEX(Entregables!$D$5:$D$9,MATCH(3,Entregables!$AG$5:$AG$9,0)),"") | C46: =IFERROR(INDEX(Entregables!$E$5:$E$9,MATCH(3,Entregables!$AG$5:$AG$9,0)),"") | D46: =IFERROR(INDEX(Entregables!$H$5:$H$9,MATCH(3,Entregables!$AG$5:$AG$9,0)),"") | E46: =IFERROR(INDEX(Entregables!$R$5:$R$9,MATCH(3,Entregables!$AG$5:$AG$9,0)),"") | F46: =IFERROR(INDEX(Entregables!$S$5:$S$9,MATCH(3,Entregables!$AG$5:$AG$9,0)),"") | G46: =IFERROR(INDEX(Entregables!$T$5:$T$9,MATCH(3,Entregables!$AG$5:$AG$9,0)),"") | H46: =IFERROR(INDEX(Entregables!$K$5:$K$9,MATCH(3,Entregables!$AG$5:$AG$9,0)),"") | I46: =IFERROR(IF(INDEX(Entregables!$M$5:$M$9,MATCH(3,Entregables!$AG$5:$AG$9,0))="","",INDEX(Entregables!$M$5:$M$9,MATCH(3,Entregables!$AG$5:$AG$9,0))),"")
B47: =IFERROR(INDEX(Entregables!$D$5:$D$9,MATCH(4,Entregables!$AG$5:$AG$9,0)),"") | C47: =IFERROR(INDEX(Entregables!$E$5:$E$9,MATCH(4,Entregables!$AG$5:$AG$9,0)),"") | D47: =IFERROR(INDEX(Entregables!$H$5:$H$9,MATCH(4,Entregables!$AG$5:$AG$9,0)),"") | E47: =IFERROR(INDEX(Entregables!$R$5:$R$9,MATCH(4,Entregables!$AG$5:$AG$9,0)),"") | F47: =IFERROR(INDEX(Entregables!$S$5:$S$9,MATCH(4,Entregables!$AG$5:$AG$9,0)),"") | G47: =IFERROR(INDEX(Entregables!$T$5:$T$9,MATCH(4,Entregables!$AG$5:$AG$9,0)),"") | H47: =IFERROR(INDEX(Entregables!$K$5:$K$9,MATCH(4,Entregables!$AG$5:$AG$9,0)),"") | I47: =IFERROR(IF(INDEX(Entregables!$M$5:$M$9,MATCH(4,Entregables!$AG$5:$AG$9,0))="","",INDEX(Entregables!$M$5:$M$9,MATCH(4,Entregables!$AG$5:$AG$9,0))),"")
...

Sheet Línea de tiempo
B1: ← Volver al Panel
B2: Línea de tiempo semanal (plazos de la Adenda N.° 01)
B3: Cada celda es una semana (empieza en lunes). El color sigue el estado de cada producto; la columna amarilla y ▼ marcan la semana de la fecha de referencia.
F5: =F6 -> 45943 | G5: =IF(DAY(G6)<=7,G6,"") | H5: =IF(DAY(H6)<=7,H6,"") | I5: =IF(DAY(I6)<=7,I6,"") -> 45964 | J5: =IF(DAY(J6)<=7,J6,"") | K5: =IF(DAY(K6)<=7,K6,"") | L5: =IF(DAY(L6)<=7,L6,"") | M5: =IF(DAY(M6)<=7,M6,"") -> 45992 | N5: =IF(DAY(N6)<=7,N6,"") | ... CS5: =IF(DAY(CS6)<=7,CS6,"")
F6: =Inicio-WEEKDAY(Inicio,3) -> 45943 | G6: =F6+7 -> 45950 | H6: =G6+7 -> 45957 | I6: =H6+7 -> 45964 | J6: =I6+7 -> 45971 | K6: =J6+7 -> 45978 | L6: =K6+7 -> 45985 | M6: =L6+7 -> 45992 | N6: =M6+7 -> 45999 | ... CS6: =CR6+7 -> 46580
B7: Producto | C7: Inicio | D7: Fecha límite | E7: Estado | F7: =IF(AND(FechaRef>=F6,FechaRef<F6+7),"▼","") | G7: =IF(AND(FechaRef>=G6,FechaRef<G6+7),"▼","") | H7: =IF(AND(FechaRef>=H6,FechaRef<H6+7),"▼","") | I7: =IF(AND(FechaRef>=I6,FechaRef<I6+7),"▼","") | J7: =IF(AND(FechaRef>=J6,FechaRef<J6+7),"▼","") | K7: =IF(AND(FechaRef>=K6,FechaRef<K6+7),"▼","") | L7: =IF(AND(FechaRef>=L6,FechaRef<L6+7),"▼","") | M7: =IF(AND(FechaRef>=M6,FechaRef<M6+7),"▼","") | ... CS7: =IF(AND(FechaRef>=CS6,FechaRef<CS6+7),"▼","")
B8: =Entregables!D5 -> Producto 1 | C8: =Entregables!G5 -> 45946 | D8: =Entregables!H5 -> 46011 | E8: =Entregables!S5 -> En revisión
B9: =Entregables!D6 -> Producto 2 · Parte I | C9: =Entregables!G6 -> 46012 | D9: =Entregables!H6 -> 46142 | E9: =Entregables!S6 -> Vencido
B10: =Entregables!D7 -> Producto 2 · Parte II | C10: =Entregables!G7 -> 46143 | D10: =Entregables!H7 -> 46203 | E10: =Entregables!S7 -> Vencido
B11: =Entregables!D8 -> Producto 3 | C11: =Entregables!G8 -> 46204 | D11: =Entregables!H8 -> 46374 | E11: =Entregables!S8 -> Por entregar
B12: =Entregables!D9 -> Producto 4 | C12: =Entregables!G9 -> 46375 | D12: =Entregables!H9 -> 46507 | E12: =Entregables!S9 -> Por entregar
B13: Cierre del convenio | C13: =Entregables!H9+1 -> 46508 | D13: =Cierre -> 46535 | E13: Cierre
B15: Leyenda
C16: Por entregar
C17: Por vencer
C18: Vencido
C19: En revisión
C20: Observado
C21: Aprobado
C22: Cierre del convenio
C23: Semana de referencia

Sheet Comparativo
B1: ← Volver al Panel
B2: Comparativo: convenio original frente a la Adenda N.° 01
B3: Cómo cambiaron los plazos de los productos y por qué las fechas de pago de la cláusula 9.1 ya no coinciden con los entregables.
B5: 1. Plazos de los productos: convenio original y Adenda N.° 01
B6: Producto | C6: Cláusula 6 original (días) | D6: Fecha original | E6: Anexo I y cl. 9.1 (días) | F6: Fecha Anexo I | G6: Adenda N.° 01 (días) | H6: Fecha vigente | I6: Prórroga (días)
B7: Producto 1 | C7: =Entregables!V5 -> 15 | D7: =Inicio+C7 -> 45961 | E7: 15 | F7: =Inicio+E7 -> 45961 | G7: =Entregables!F5 -> 65 | H7: =Inicio+G7 -> 46011 | I7: =G7-C7 -> 50
B8: Producto 2 · Parte I | C8: =Entregables!V6 -> 180 | D8: =Inicio+C8 -> 46126 | E8: 120 | F8: =Inicio+E8 -> 46066 | G8: =Entregables!F6 -> 196 | H8: =Inicio+G8 -> 46142 | I8: =G8-C8 -> 16
B9: Producto 2 · Parte II | C9: =Entregables!V7 -> 180 | D9: =Inicio+C9 -> 46126 | E9: 120 | F9: =Inicio+E9 -> 46066 | G9: =Entregables!F7 -> 257 | H9: =Inicio+G9 -> 46203 | I9: =G9-C9 -> 77
B10: Producto 3 | C10: =Entregables!V8 -> 360 | D10: =Inicio+C10 -> 46306 | E10: 240 | F10: =Inicio+E10 -> 46186 | G10: =Entregables!F8 -> 428 | H10: =Inicio+G10 -> 46374 | I10: =G10-C10 -> 68
B11: Producto 4 | C11: =Entregables!V9 -> 540 | D11: =Inicio+C11 -> 46486 | E11: 495 | F11: =Inicio+E11 -> 46441 | G11: =Entregables!F9 -> 561 | H11: =Inicio+G11 -> 46507 | I11: =G11-C11 -> 21
B12: Fin del convenio | C12: =FinOriginal -> 540 | D12: =Inicio+C12 -> 46486 | E12: =FinOriginal -> 540 | F12: =Inicio+E12 -> 46486 | G12: =DiasConvenio -> 589 | H12: =Inicio+G12 -> 46535 | I12: =G12-C12 -> 49
B13: En el convenio original el Producto 2 era un solo entregable (día 180); la Adenda lo divide en Parte I (día 196) y Parte II (día 257).
B15: 2. Cada pago frente al entregable que lo habilita
B16: Desembolso | C16: Monto (S/) | D16: Fecha según 9.1 | E16: Producto que lo habilita | F16: Fecha límite vigente | G16: Diferencia (días) | H16: Estado del pago
